Workbook

Sheet Overview
A1: SMS survey question bank - eCooking & daytime load-shifting
A2: Rural Kenya PV microgrid customers | Two-way SMS, numbered replies | English & Kiswahili
A4: Purpose
A5: Understand cooking fuel choices, cooking times, barriers to daytime and electric cooking, and test incentives that shift cooking into the 10am-3pm solar window. Rewards are free electricity credits valid in that window. Smart-meter data (household kWh by time of day) is the objective outcome measure; surveys capture the why.
A9: Modules
A10: Module | B10: Questions | C10: Cadence | D10: Est. time | E10: Suggested reward
A11: Enrolment & consent | B11: =COUNTIF('Question bank'!A:A,A11) -> 4 | C11: One-time, day 0 | D11: 2 min | E11: Welcome credit 0.5 kWh
A12: Baseline | B12: =COUNTIF('Question bank'!A:A,A12) -> 24 | C12: 3 sessions in week 0 (days 1, 3, 5) | D12: 3-4 min each | E12: 1.0 kWh per session
A13: Weekly pulse | B13: =COUNTIF('Question bank'!A:A,A13) -> 8 | C13: Every week, 3-5 questions | D13: under 2 min | E13: 0.4 kWh (one EPC meal)
A14: Monthly | B14: =COUNTIF('Question bank'!A:A,A14) -> 9 | C14: Week 4 of each month, replaces pulse | D14: 3 min | E14: 0.7 kWh
A15: Quarterly | B15: =COUNTIF('Question bank'!A:A,A15) -> 6 | C15: Months 3, 6, 9, 12, appended to monthly | D15: 4 min | E15: 1.0 kWh
A16: System messages | B16: =COUNTIF('Question bank'!A:A,A16) -> 5 | C16: Triggered | D16: - | E16: -
A18: How to use this workbook
A19: - Question bank: every SMS as sent, in both languages, with live character counts (LEN formulas) and routing.
A20: - Schedule & rotation: which questions go out in which week, and the annual calendar.
A21: - Incentive design: reward sizing (editable blue inputs) and the randomised credit-window experiment.
A22: - Codebook: variable names and value labels for the analysis dataset.
A23: - Texts over 160 GSM-7 characters are flagged in the Segments columns; keep every message to 1 SMS where possible.

Sheet Question bank
A1: Module | B1: Wave / timing | C1: QID | D1: Variable | E1: Type | F1: SMS text (English) | G1: Chars EN | H1: SMS EN | I1: SMS text (Kiswahili) | J1: Chars SW | K1: SMS SW | L1: Valid replies | M1: Routing / skip logic | N1: What it measures | O1: Notes
A2: Enrolment & consent | B2: Day 0 | C2: S0 | D2: lang_pref | E2: single | F2: Habari! Hii ni [UTILITY]. Kwa maswali kwa Kiswahili, jibu 1. For questions in English, reply 2. | G2: =LEN(F2) -> 95 | H2: =IF(G2<=160,"1 SMS",ROUNDUP(G2/153,0)&" SMS") -> 1 SMS | I2: Habari! Hii ni [UTILITY]. Kwa maswali kwa Kiswahili, jibu 1. For questions in English, reply 2. | J2: =LEN(I2) -> 95 | K2: =IF(J2<=160,"1 SMS",ROUNDUP(J2/153,0)&" SMS") -> 1 SMS | L2: 1-2 | N2: Language routing for all later messages | O2: Single bilingual message; sets language flag for the household
A3: Enrolment & consent | B3: Day 0 | C3: S1 | D3: consent | E3: single | F3: We invite you to short SMS surveys about cooking and power. Each completed survey earns FREE units. Reply YES to join or NO. Text STOP anytime to leave. | G3: =LEN(F3) -> 152 | H3: =IF(G3<=160,"1 SMS",ROUNDUP(G3/153,0)&" SMS") -> 1 SMS | I3: Tunakualika kwenye maswali mafupi ya SMS kuhusu upishi na umeme. Ukimaliza unapata units za BURE. Jibu NDIYO kujiunga au HAPANA. Tuma ACHA kuacha. | J3: =LEN(I3) -> 146 | K3: =IF(J3<=160,"1 SMS",ROUNDUP(J3/153,0)&" SMS") -> 1 SMS | L3: YES/NO or NDIYO/HAPANA | M3: If NO: send thanks, no further contact | N3: Informed consent (Kenya DPA 2019) | O3: Log consent timestamp against account ID
A4: Enrolment & consent | B4: Day 0 | C4: S2 | E4: system | F4: Thank you for joining! Rewards are FREE daytime units usable 10am-3pm (saa 4 asubuhi-saa 9 alasiri) when solar power is strongest. Questions start tomorrow. | G4: =LEN(F4) -> 156 | H4: =IF(G4<=160,"1 SMS",ROUNDUP(G4/153,0)&" SMS") -> 1 SMS | I4: Asante kwa kujiunga! Zawadi ni units za BURE za mchana, zinatumika 10am-3pm (saa 4 asubuhi - saa 9 alasiri) wakati nguvu ya jua iko juu. Maswali huanza kesho. | J4: =LEN(I4) -> 158 | K4: =IF(J4<=160,"1 SMS",ROUNDUP(J4/153,0)&" SMS") -> 1 SMS | N4: Defines the daytime window once, in both clock conventions | O4: Window definition is reused implicitly by all later questions
A5: Enrolment & consent | B5: Day 0 | C5: C1 | D5: main_cook | E5: single | F5: Are you the person who cooks most meals in your home? 1=Yes 2=I cook sometimes 3=I rarely cook | G5: =LEN(F5) -> 94 | H5: =IF(G5<=160,"1 SMS",ROUNDUP(G5/153,0)&" SMS") -> 1 SMS | I5: Je, wewe ndiye unayepika mara nyingi nyumbani? 1=Ndiyo 2=Napika mara kwa mara tu 3=Sipiki sana | J5: =LEN(I5) -> 94 | K5: =IF(J5<=160,"1 SMS",ROUNDUP(J5/153,0)&" SMS") -> 1 SMS | L5: 1-3 | M5: If 3: send SYS_PASS asking to hand phone to main cook | N5: Respondent identity; key covariate (proxy reporting) | O5: Phone owner is often not the cook; record and re-ask at re-baseline
A6: Baseline | B6: S1 Day 1 | C6: B1 | D6: hh_size | E6: numeric | F6: How many people usually eat the evening meal in your home? Reply with a number, e.g. 5 | G6: =LEN(F6) -> 86 | H6: =IF(G6<=160,"1 SMS",ROUNDUP(G6/153,0)&" SMS") -> 1 SMS | I6: Kwa kawaida watu wangapi hula chakula cha jioni nyumbani kwako? Jibu kwa namba, mfano 5 | J6: =LEN(I6) -> 87 | K6: =IF(J6<=160,"1 SMS",ROUNDUP(J6/153,0)&" SMS") -> 1 SMS | L6: 1-30 | N6: Household size; denominator for per-capita use | O6: Validate 1-30; re-ask once if out of range
A7: Baseline | B7: S1 Day 1 | C7: B2 | D7: hh_under5 | E7: numeric | F7: How many children under 5 years live in your home? Reply with a number. Reply 0 if none | G7: =LEN(F7) -> 87 | H7: =IF(G7<=160,"1 SMS",ROUNDUP(G7/153,0)&" SMS") -> 1 SMS | I7: Watoto wangapi chini ya miaka 5 wanaishi nyumbani kwako? Jibu kwa namba. Jibu 0 kama hakuna | J7: =LEN(I7) -> 91 | K7: =IF(J7<=160,"1 SMS",ROUNDUP(J7/153,0)&" SMS") -> 1 SMS | L7: 0-15 | N7: Child presence: cooking frequency & indoor smoke exposure
A8: Baseline | B8: S1 Day 1 | C8: B3 | D8: phone_owner | E8: single | F8: Whose phone is receiving these messages? 1=Mine 2=My spouse's 3=Shared family phone 4=Other | G8: =LEN(F8) -> 91 | H8: =IF(G8<=160,"1 SMS",ROUNDUP(G8/153,0)&" SMS") -> 1 SMS | I8: Simu inayopokea ujumbe huu ni ya nani? 1=Yangu 2=Ya mke/mume wangu 3=Ya familia 4=Nyingine | J8: =LEN(I8) -> 90 | K8: =IF(J8<=160,"1 SMS",ROUNDUP(J8/153,0)&" SMS") -> 1 SMS | L8: 1-4 | N8: Who actually answers; response quality covariate
A9: Baseline | B9: S1 Day 1 | C9: B4 | D9: income_src | E9: single | F9: What is your household's main source of income? 1=Farming 2=Own business 3=Casual work 4=Salary 5=Other | G9: =LEN(F9) -> 103 | H9: =IF(G9<=160,"1 SMS",ROUNDUP(G9/153,0)&" SMS") -> 1 SMS | I9: Kipato kikuu cha nyumba yako ni nini? 1=Kilimo 2=Biashara yangu 3=Vibarua 4=Mshahara 5=Nyingine | J9: =LEN(I9) -> 95 | K9: =IF(J9<=160,"1 SMS",ROUNDUP(J9/153,0)&" SMS") -> 1 SMS | L9: 1-5 | N9: Livelihood: predicts daytime availability & ability to pay
A10: Baseline | B10: S1 Day 1 | C10: B5 | D10: fuel_decider | E10: single | F10: Who decides how money is spent on cooking fuel? 1=Me 2=My spouse 3=We decide together 4=Someone else | G10: =LEN(F10) -> 100 | H10: =IF(G10<=160,"1 SMS",ROUNDUP(G10/153,0)&" SMS") -> 1 SMS | I10: Nani huamua matumizi ya pesa za nishati ya kupikia? 1=Mimi 2=Mke/mume wangu 3=Tunaamua pamoja 4=Mtu mwingine | J10: =LEN(I10) -> 108 | K10: =IF(J10<=160,"1 SMS",ROUNDUP(J10/153,0)&" SMS") -> 1 SMS | L10: 1-4 | N10: Intra-household decision making; who incentives must reach
A11: Baseline | B11: S1 Day 1 | C11: B6 | D11: home_midday | E11: single | F11: On most days, are you at home between 10am and 3pm? 1=Yes, most days 2=Some days 3=Rarely | G11: =LEN(F11) -> 89 | H11: =IF(G11<=160,"1 SMS",ROUNDUP(G11/153,0)&" SMS") -> 1 SMS | I11: Siku nyingi, uko nyumbani kati ya 10am na 3pm (saa 4 - saa 9 mchana)? 1=Ndiyo siku nyingi 2=Siku zingine 3=Mara chache | J11: =LEN(I11) -> 118 | K11: =IF(J11<=160,"1 SMS",ROUNDUP(J11/153,0)&" SMS") -> 1 SMS | L11: 1-3 | N11: Physical availability: hard constraint on daytime cooking | O11: Key segmentation variable for incentive targeting
A12: Baseline | B12: S2 Day 3 | C12: B7 | D12: own_epc | E12: single | F12: Do you have an electric pressure cooker (EPC)? 1=Yes, working 2=Yes, but broken 3=No | G12: =LEN(F12) -> 84 | H12: =IF(G12<=160,"1 SMS",ROUNDUP(G12/153,0)&" SMS") -> 1 SMS | I12: Je, una jiko la shinikizo la umeme (EPC)? 1=Ndiyo, linafanya kazi 2=Ndiyo, lakini ni bovu 3=Sina | J12: =LEN(I12) -> 96 | K12: =IF(J12<=160,"1 SMS",ROUNDUP(J12/153,0)&" SMS") -> 1 SMS | L12: 1-3 | M12: If B7=3 and B8=3: skip W4-W7 in weekly pulse | N12: Appliance access | O12: Broken EPCs are a service opportunity; flag for follow-up
A13: Baseline | B13: S2 Day 3 | C13: B8 | D13: own_hob | E13: single | F13: Do you have an electric hob or hotplate? 1=Yes, working 2=Yes, but broken 3=No | G13: =LEN(F13) -> 78 | H13: =IF(G13<=160,"1 SMS",ROUNDUP(G13/153,0)&" SMS") -> 1 SMS | I13: Je, una jiko la umeme la sahani (hotplate)? 1=Ndiyo, linafanya kazi 2=Ndiyo, lakini ni bovu 3=Sina | J13: =LEN(I13) -> 98 | K13: =IF(J13<=160,"1 SMS",ROUNDUP(J13/153,0)&" SMS") -> 1 SMS | L13: 1-3 | M13: See B7 | N13: Appliance access
A14: Baseline | B14: S2 Day 3 | C14: B9 | D14: fuels_7d | E14: multi | F14: Which did you use for cooking in the past 7 days? Reply all that apply, e.g. 1,3: 1=Firewood 2=Charcoal 3=LPG gas 4=Electricity 5=Kerosene | G14: =LEN(F14) -> 138 | H14: =IF(G14<=160,"1 SMS",ROUNDUP(G14/153,0)&" SMS") -> 1 SMS | I14: Ulitumia nini kupika siku 7 zilizopita? Jibu zote, mfano 1,3: 1=Kuni 2=Makaa 3=Gesi 4=Umeme 5=Mafuta ya taa | J14: =LEN(I14) -> 107 | K14: =IF(J14<=160,"1 SMS",ROUNDUP(J14/153,0)&" SMS") -> 1 SMS | L14: 1-5, comma separated | N14: Fuel stack (baseline) | O14: Multi-select replies are error-prone: pilot carefully
A15: Baseline | B15: S2 Day 3 | C15: B10 | D15: fuel_main | E15: single | F15: Which ONE do you use MOST to cook the main meal? 1=Firewood 2=Charcoal 3=LPG gas 4=Electricity 5=Kerosene | G15: =LEN(F15) -> 105 | H15: =IF(G15<=160,"1 SMS",ROUNDUP(G15/153,0)&" SMS") -> 1 SMS | I15: Unatumia nini ZAIDI kupika chakula kikuu? Chagua MOJA: 1=Kuni 2=Makaa 3=Gesi 4=Umeme 5=Mafuta ya taa | J15: =LEN(I15) -> 100 | K15: =IF(J15<=160,"1 SMS",ROUNDUP(J15/153,0)&" SMS") -> 1 SMS | L15: 1-5 | N15: Primary fuel (baseline anchor for switching)
A16: Baseline | B16: S2 Day 3 | C16: B11 | D16: fuel_why | E16: single | F16: Main reason you use that fuel most? 1=Cheapest 2=Cooks fastest 3=Food tastes better 4=Easy to get 5=I know it best | G16: =LEN(F16) -> 114 | H16: =IF(G16<=160,"1 SMS",ROUNDUP(G16/153,0)&" SMS") -> 1 SMS | I16: Sababu kuu ya kutumia nishati hiyo zaidi? 1=Bei nafuu 2=Inapika haraka 3=Chakula kitamu zaidi 4=Rahisi kupata 5=Naifahamu zaidi | J16: =LEN(I16) -> 127 | K16: =IF(J16<=160,"1 SMS",ROUNDUP(J16/153,0)&" SMS") -> 1 SMS | L16: 1-5 | N16: Fuel choice motivation (core objective)
A17: Baseline | B17: S2 Day 3 | C17: B12 | D17: fuel_spend_7d | E17: single | F17: How much did your home spend on charcoal, LPG or kerosene in the last 7 days? 1=Nothing 2=Under 100 3=100-300 4=301-500 5=Over 500 (KSh) | G17: =LEN(F17) -> 136 | H17: =IF(G17<=160,"1 SMS",ROUNDUP(G17/153,0)&" SMS") -> 1 SMS | I17: Mlitumia pesa ngapi kwa makaa, gesi au mafuta ya taa siku 7 zilizopita? 1=Hakuna 2=Chini ya 100 3=100-300 4=301-500 5=Zaidi ya 500 (KSh) | J17: =LEN(I17) -> 136 | K17: =IF(J17<=160,"1 SMS",ROUNDUP(J17/153,0)&" SMS") -> 1 SMS | L17: 1-5 | N17: Fuel expenditure: sizes the economic case for switching | O17: Banded to reduce recall burden
A18: Baseline | B18: S2 Day 3 | C18: B13 | D18: wood_hours | E18: single | F18: How many hours a week does your household spend collecting firewood? 1=None 2=Under 2 3=2-5 4=6-10 5=Over 10 | G18: =LEN(F18) -> 108 | H18: =IF(G18<=160,"1 SMS",ROUNDUP(G18/153,0)&" SMS") -> 1 SMS | I18: Nyumba yako hutumia saa ngapi kwa wiki kutafuta kuni? 1=Hakuna 2=Chini ya 2 3=2-5 4=6-10 5=Zaidi ya 10 | J18: =LEN(I18) -> 102 | K18: =IF(J18<=160,"1 SMS",ROUNDUP(J18/153,0)&" SMS") -> 1 SMS | L18: 1-5 | N18: Time cost of firewood: the freed-time opportunity | O18: Repeated monthly (M3) for trend
A19: Baseline | B19: S2 Day 3 | C19: B14 | D19: meals_yday | E19: multi | F19: Which meals did you cook yesterday? Reply all, e.g. 1,3: 1=Breakfast 2=Lunch 3=Supper 4=Did not cook | G19: =LEN(F19) -> 100 | H19: =IF(G19<=160,"1 SMS",ROUNDUP(G19/153,0)&" SMS") -> 1 SMS | I19: Ulipika milo gani jana? Jibu zote, mfano 1,3: 1=Asubuhi 2=Mchana 3=Jioni 4=Sikupika | J19: =LEN(I19) -> 83 | K19: =IF(J19<=160,"1 SMS",ROUNDUP(J19/153,0)&" SMS") -> 1 SMS | L19: 1-4, comma separated | N19: Meal pattern: is there a midday meal to shift?
A20: Baseline | B20: S2 Day 3 | C20: B15 | D20: meal_biggest | E20: single | F20: Which is the biggest meal cooked in your home? 1=Breakfast 2=Lunch 3=Supper | G20: =LEN(F20) -> 75 | H20: =IF(G20<=160,"1 SMS",ROUNDUP(G20/153,0)&" SMS") -> 1 SMS | I20: Mlo mkubwa nyumbani kwako ni upi? 1=Wa asubuhi 2=Wa mchana 3=Wa jioni | J20: =LEN(I20) -> 69 | K20: =IF(J20<=160,"1 SMS",ROUNDUP(J20/153,0)&" SMS") -> 1 SMS | L20: 1-3 | N20: Where the energy goes; supper-dominant homes are hardest to shift
A21: Baseline | B21: S2 Day 3 | C21: B16 | D21: longboil_freq | E21: single | F21: How often do you cook githeri, beans or other foods that boil for long? 1=Most days 2=1-3 times a week 3=Rarely 4=Never | G21: =LEN(F21) -> 119 | H21: =IF(G21<=160,"1 SMS",ROUNDUP(G21/153,0)&" SMS") -> 1 SMS | I21: Unapika githeri, maharagwe au vyakula vya kuchemshwa muda mrefu mara ngapi? 1=Karibu kila siku 2=Mara 1-3 kwa wiki 3=Mara chache 4=Kamwe | J21: =LEN(I21) -> 136 | K21: =IF(J21<=160,"1 SMS",ROUNDUP(J21/153,0)&" SMS") -> 1 SMS | L21: 1-4 | N21: Long-boil dishes are the EPC sweet spot and biggest fuel saving | O21: Target EPC promotion at frequent long-boil cooks
A22: Baseline | B22: S3 Day 5 | C22: B17 | D22: time_driver | E22: single | F22: What most decides WHAT TIME you cook? 1=Farm or work hours 2=When family is home 3=When fuel or stove is ready 4=Habit 5=Other | G22: =LEN(F22) -> 126 | H22: =IF(G22<=160,"1 SMS",ROUNDUP(G22/153,0)&" SMS") -> 1 SMS | I22: Nini huamua zaidi WAKATI unapopika? 1=Kazi au shamba 2=Familia wakiwa nyumbani 3=Nishati au jiko tayari 4=Mazoea 5=Nyingine | J22: =LEN(I22) -> 123 | K22: =IF(J22<=160,"1 SMS",ROUNDUP(J22/153,0)&" SMS") -> 1 SMS | L22: 1-5 | N22: Timing motivation (core objective)
A23: Baseline | B23: S3 Day 5 | C23: B18 | D23: midday_freq | E23: single | F23: Do you cook anything between 10am and 3pm? 1=Most days 2=Some days 3=Rarely or never | G23: =LEN(F23) -> 84 | H23: =IF(G23<=160,"1 SMS",ROUNDUP(G23/153,0)&" SMS") -> 1 SMS | I23: Je, unapika chochote kati ya 10am na 3pm (saa 4 - saa 9 mchana)? 1=Siku nyingi 2=Siku zingine 3=Mara chache | J23: =LEN(I23) -> 107 | K23: =IF(J23<=160,"1 SMS",ROUNDUP(J23/153,0)&" SMS") -> 1 SMS | L23: 1-3 | N23: Self-reported daytime cooking; validate against meter data
A24: Baseline | B24: S3 Day 5 | C24: B19 | D24: midday_barrier | E24: single | F24: Main reason you do not cook more at midday? 1=Away at farm or market 2=Main meal is at night 3=No one home then 4=Cost of units 5=Other | G24: =LEN(F24) -> 135 | H24: =IF(G24<=160,"1 SMS",ROUNDUP(G24/153,0)&" SMS") -> 1 SMS | I24: Sababu kuu ya kutopika zaidi mchana? 1=Niko shambani au sokoni 2=Chakula kikuu ni cha jioni 3=Hakuna mtu nyumbani 4=Gharama ya units 5=Nyingine | J24: =LEN(I24) -> 143 | K24: =IF(J24<=160,"1 SMS",ROUNDUP(J24/153,0)&" SMS") -> 1 SMS | L24: 1-5 | N24: Daytime barrier (core objective)
A25: Baseline | B25: S3 Day 5 | C25: B20 | D25: ecook_barrier | E25: single | F25: What most stops you cooking with electricity? 1=Cost of units 2=Fear of the appliance 3=Food taste 4=Appliance broken or too small 5=Power cuts | G25: =LEN(F25) -> 143 | H25: =IF(G25<=160,"1 SMS",ROUNDUP(G25/153,0)&" SMS") -> 1 SMS | I25: Nini kinakuzuia zaidi kupika kwa umeme? 1=Gharama ya units 2=Hofu ya kifaa 3=Ladha ya chakula 4=Kifaa ni kibovu au kidogo 5=Umeme kukatika | J25: =LEN(I25) -> 138 | K25: =IF(J25<=160,"1 SMS",ROUNDUP(J25/153,0)&" SMS") -> 1 SMS | L25: 1-5 | N25: eCooking barrier (core objective)
A26: Baseline | B26: S3 Day 5 | C26: B21 | D26: free_units_intent | E26: single | F26: If you got FREE units usable only 10am-3pm, would you cook lunch with electricity? 1=Yes 2=Maybe 3=No | G26: =LEN(F26) -> 101 | H26: =IF(G26<=160,"1 SMS",ROUNDUP(G26/153,0)&" SMS") -> 1 SMS | I26: Ukipata units za BURE za kutumia 10am-3pm tu, ungepika chakula cha mchana kwa umeme? 1=Ndiyo 2=Labda 3=Hapana | J26: =LEN(I26) -> 109 | K26: =IF(J26<=160,"1 SMS",ROUNDUP(J26/153,0)&" SMS") -> 1 SMS | L26: 1-3 | N26: Stated response to the core incentive; compare with revealed behaviour
A27: Baseline | B27: S3 Day 5 | C27: B22 | D27: freed_time_use | E27: single | F27: If cooking took 2 hours less each day, what would you do with that time? 1=Farming 2=Small business like sewing or selling 3=Childcare 4=Rest 5=Study | G27: =LEN(F27) -> 149 | H27: =IF(G27<=160,"1 SMS",ROUNDUP(G27/153,0)&" SMS") -> 1 SMS | I27: Kama kupika kungechukua saa 2 pungufu kwa siku, ungefanya nini na muda huo? 1=Kilimo 2=Biashara ndogo kama kushona au kuuza 3=Kulea watoto 4=Kupumzika 5=Kusoma | J27: =LEN(I27) -> 159 | K27: =IF(J27<=160,"1 SMS",ROUNDUP(J27/153,0)&" SMS") -> 1 SMS | L27: 1-5 | N27: Freed-time economic potential (core objective)
A28: Baseline | B28: S3 Day 5 | C28: B23 | D28: income_interest | E28: single | F28: If you had more free time, would you start or grow an activity that earns money? 1=Yes, very much 2=Maybe 3=No | G28: =LEN(F28) -> 110 | H28: =IF(G28<=160,"1 SMS",ROUNDUP(G28/153,0)&" SMS") -> 1 SMS | I28: Ukipata muda zaidi, ungeanzisha au kukuza shughuli ya kipato? 1=Ndiyo, sana 2=Labda 3=Hapana | J28: =LEN(I28) -> 92 | K28: =IF(J28<=160,"1 SMS",ROUNDUP(J28/153,0)&" SMS") -> 1 SMS | L28: 1-3 | N28: Appetite for productive use of freed time & electricity
A29: Baseline | B29: S3 Day 5 | C29: B24 | D29: sms_time_pref | E29: single | F29: What time is best to send you these questions? 1=Morning 2=Midday 3=Evening | G29: =LEN(F29) -> 75 | H29: =IF(G29<=160,"1 SMS",ROUNDUP(G29/153,0)&" SMS") -> 1 SMS | I29: Wakati gani ni mzuri kukutumia maswali haya? 1=Asubuhi 2=Mchana 3=Jioni | J29: =LEN(I29) -> 71 | K29: =IF(J29<=160,"1 SMS",ROUNDUP(J29/153,0)&" SMS") -> 1 SMS | L29: 1-3 | N29: Maximise response rates | O29: Drives per-household send scheduling
A30: Weekly pulse | B30: Anchor, every week | C30: W1 | D30: w_fuels_yday | E30: multi | F30: Yesterday, which did you use to cook? Reply all, e.g. 1,4: 1=Firewood 2=Charcoal 3=LPG gas 4=Electricity 5=Did not cook | G30: =LEN(F30) -> 119 | H30: =IF(G30<=160,"1 SMS",ROUNDUP(G30/153,0)&" SMS") -> 1 SMS | I30: Jana ulitumia nini kupika? Jibu zote, mfano 1,4: 1=Kuni 2=Makaa 3=Gesi 4=Umeme 5=Sikupika | J30: =LEN(I30) -> 89 | K30: =IF(J30<=160,"1 SMS",ROUNDUP(J30/153,0)&" SMS") -> 1 SMS | L30: 1-5, comma separated | N30: Fuel stack trend; day-recall reduces bias | O30: Anchor question: identical wording every week
A31: Weekly pulse | B31: Anchor, every week | C31: W2 | D31: w_midday_cooked | E31: single | F31: Did you cook anything between 10am and 3pm yesterday? 1=Yes 2=No | G31: =LEN(F31) -> 64 | H31: =IF(G31<=160,"1 SMS",ROUNDUP(G31/153,0)&" SMS") -> 1 SMS | I31: Ulipika chochote kati ya 10am na 3pm jana? 1=Ndiyo 2=Hapana | J31: =LEN(I31) -> 59 | K31: =IF(J31<=160,"1 SMS",ROUNDUP(J31/153,0)&" SMS") -> 1 SMS | L31: 1-2 | M31: If 2: send W3 | N31: Daytime cooking trend; validate against meter | O31: Anchor question
A32: Weekly pulse | B32: Conditional on W2=No | C32: W3 | D32: w_midday_barrier | E32: single | F32: What stopped you cooking at midday yesterday? 1=Away from home 2=No meal needed then 3=Units finished 4=Power problem 5=Other | G32: =LEN(F32) -> 125 | H32: =IF(G32<=160,"1 SMS",ROUNDUP(G32/153,0)&" SMS") -> 1 SMS | I32: Nini kilikuzuia kupika mchana jana? 1=Sikuwa nyumbani 2=Sikuhitaji mlo 3=Units ziliisha 4=Shida ya umeme 5=Nyingine | J32: =LEN(I32) -> 115 | K32: =IF(J32<=160,"1 SMS",ROUNDUP(J32/153,0)&" SMS") -> 1 SMS | L32: 1-5 | M32: Only if W2=2 | N32: Time-varying daytime barriers
A33: Weekly pulse | B33: Rotating | C33: W4 | D33: w_appliance_use | E33: single | F33: Did you use the EPC or electric hob in the past 7 days? 1=Both 2=EPC only 3=Hob only 4=Neither | G33: =LEN(F33) -> 94 | H33: =IF(G33<=160,"1 SMS",ROUNDUP(G33/153,0)&" SMS") -> 1 SMS | I33: Ulitumia EPC au jiko la umeme siku 7 zilizopita? 1=Vyote viwili 2=EPC tu 3=Jiko la sahani tu 4=Hakuna | J33: =LEN(I33) -> 101 | K33: =IF(J33<=160,"1 SMS",ROUNDUP(J33/153,0)&" SMS") -> 1 SMS | L33: 1-4 | M33: Skip if B7=3 and B8=3. If 4: skip W5 | N33: Appliance usage split
A34: Weekly pulse | B34: Conditional on W4=1-3 | C34: W5 | D34: w_edish | E34: multi | F34: What did you cook with electricity this week? Reply all: 1=Ugali 2=Githeri or beans 3=Rice 4=Tea or hot water 5=Other | G34: =LEN(F34) -> 117 | H34: =IF(G34<=160,"1 SMS",ROUNDUP(G34/153,0)&" SMS") -> 1 SMS | I34: Ulipika nini kwa umeme wiki hii? Jibu zote: 1=Ugali 2=Githeri au maharagwe 3=Wali 4=Chai au maji moto 5=Nyingine | J34: =LEN(I34) -> 112 | K34: =IF(J34<=160,"1 SMS",ROUNDUP(J34/153,0)&" SMS") -> 1 SMS | L34: 1-5, comma separated | M34: Only if W4 in 1-3 | N34: Dish adoption: which foods migrate to electricity first
A35: Weekly pulse | B35: Rotating | C35: W6 | D35: w_problem | E35: single | F35: Any problem cooking with electricity this week? 1=No problem 2=Power cut 3=Appliance problem 4=Units ran out 5=Other | G35: =LEN(F35) -> 116 | H35: =IF(G35<=160,"1 SMS",ROUNDUP(G35/153,0)&" SMS") -> 1 SMS | I35: Ulipata shida kupika kwa umeme wiki hii? 1=Hakuna shida 2=Umeme ulikatika 3=Shida ya kifaa 4=Units ziliisha 5=Nyingine | J35: =LEN(I35) -> 118 | K35: =IF(J35<=160,"1 SMS",ROUNDUP(J35/153,0)&" SMS") -> 1 SMS | L35: 1-5 | M35: Skip if B7=3 and B8=3 | N35: Service quality; reliability perception | O35: Route 2/3 to operations team for follow-up
A36: Weekly pulse | B36: Rotating | C36: W7 | D36: w_bonus_effect | E36: single | F36: Did your free bonus units help you cook in the daytime this week? 1=Yes 2=A little 3=No 4=I did not get units | G36: =LEN(F36) -> 109 | H36: =IF(G36<=160,"1 SMS",ROUNDUP(G36/153,0)&" SMS") -> 1 SMS | I36: Units za bure zilikusaidia kupika mchana wiki hii? 1=Ndiyo 2=Kidogo 3=Hapana 4=Sikupata units | J36: =LEN(I36) -> 93 | K36: =IF(J36<=160,"1 SMS",ROUNDUP(J36/153,0)&" SMS") -> 1 SMS | L36: 1-4 | N36: Perceived incentive effect; cross-check credit delivery | O36: Option 4 flags reward delivery failures
A37: Weekly pulse | B37: Rotating | C37: W8 | D37: w_who_cooked | E37: single | F37: Who cooked most meals in your home this week? 1=Me 2=Another adult 3=A child 4=We shared | G37: =LEN(F37) -> 88 | H37: =IF(G37<=160,"1 SMS",ROUNDUP(G37/153,0)&" SMS") -> 1 SMS | I37: Nani alipika milo mingi nyumbani wiki hii? 1=Mimi 2=Mtu mzima mwingine 3=Mtoto 4=Tulishirikiana | J37: =LEN(I37) -> 95 | K37: =IF(J37<=160,"1 SMS",ROUNDUP(J37/153,0)&" SMS") -> 1 SMS | L37: 1-4 | N37: Household changes in who cooks; proxy-reporting check
A38: Monthly | B38: Every month | C38: M1 | D38: m_spend_biomass | E38: single | F38: In the last 30 days, how much did your home spend on charcoal and firewood? 1=Nothing 2=Under 200 3=200-500 4=501-1000 5=Over 1000 (KSh) | G38: =LEN(F38) -> 136 | H38: =IF(G38<=160,"1 SMS",ROUNDUP(G38/153,0)&" SMS") -> 1 SMS | I38: Siku 30 zilizopita, mlitumia pesa ngapi kwa makaa na kuni? 1=Hakuna 2=Chini ya 200 3=200-500 4=501-1000 5=Zaidi ya 1000 (KSh) | J38: =LEN(I38) -> 125 | K38: =IF(J38<=160,"1 SMS",ROUNDUP(J38/153,0)&" SMS") -> 1 SMS | L38: 1-5 | N38: Biomass spend trend: substitution evidence
A39: Monthly | B39: Every month | C39: M2 | D39: m_spend_lpg | E39: single | F39: In the last 30 days, how much on LPG gas and kerosene? 1=Nothing 2=Under 200 3=200-500 4=501-1000 5=Over 1000 (KSh) | G39: =LEN(F39) -> 115 | H39: =IF(G39<=160,"1 SMS",ROUNDUP(G39/153,0)&" SMS") -> 1 SMS | I39: Siku 30 zilizopita, mlitumia pesa ngapi kwa gesi na mafuta ya taa? 1=Hakuna 2=Chini ya 200 3=200-500 4=501-1000 5=Zaidi ya 1000 (KSh) | J39: =LEN(I39) -> 133 | K39: =IF(J39<=160,"1 SMS",ROUNDUP(J39/153,0)&" SMS") -> 1 SMS | L39: 1-5 | N39: LPG/kerosene spend trend
A40: Monthly | B40: Every month | C40: M3 | D40: m_wood_hours | E40: single | F40: How many hours a week does your household spend collecting firewood? 1=None 2=Under 2 3=2-5 4=6-10 5=Over 10 | G40: =LEN(F40) -> 108 | H40: =IF(G40<=160,"1 SMS",ROUNDUP(G40/153,0)&" SMS") -> 1 SMS | I40: Nyumba yako hutumia saa ngapi kwa wiki kutafuta kuni? 1=Hakuna 2=Chini ya 2 3=2-5 4=6-10 5=Zaidi ya 10 | J40: =LEN(I40) -> 102 | K40: =IF(J40<=160,"1 SMS",ROUNDUP(J40/153,0)&" SMS") -> 1 SMS | L40: 1-5 | N40: Firewood time trend (same bands as B13) | O40: Identical wording to B13 for comparability
...

Sheet Schedule & rotation
A1: Survey calendar
A3: When | B3: What is sent | C3: Questions | D3: Max Qs | E3: Reward on completion
A4: Day 0 (enrolment) | B4: Language, consent, welcome, respondent check | C4: S0, S1, S2, C1 | D4: 4 | E4: 0.5 kWh welcome credit
A5: Day 1 | B5: Baseline session 1 - household | C5: B1-B6 | D5: 6 | E5: 1.0 kWh
A6: Day 3 | B6: Baseline session 2 - cooking & fuels | C6: B7-B16 | D6: 10 | E6: 1.0 kWh
A7: Day 5 | B7: Baseline session 3 - timing, barriers, aspirations | C7: B17-B24 | D7: 8 | E7: 1.0 kWh
A8: Every week (wk 1-3 of month) | B8: Weekly pulse: 2 anchors + 2 rotating | C8: W1, W2 (+W3 if needed) + 2 of W4-W8 | D8: 5 | E8: 0.4 kWh
A9: Week 4 of month | B9: Monthly module (replaces pulse) | C9: M1-M4 + M6a or M6b + M7 (+M5/M8 alternating) | D9: 7 | E9: 0.7 kWh
A10: Months 3, 6, 9, 12 | B10: Quarterly module (replaces monthly extras) | C10: M1-M4 + Q1-Q6 | D10: 10 | E10: 1.0 kWh
A11: Month 12 | B11: Re-baseline | C11: B7-B23 repeated | D11: 17 | E11: 2.0 kWh
A13: Weekly rotation (repeats every 4 weeks)
A14: Week of month | B14: Anchors | C14: Rotating slot 1 | D14: Rotating slot 2 | E14: Conditional
A15: Week 1 | B15: W1, W2 | C15: W4 appliance use | D15: W5 dishes cooked | E15: W3 if W2=No; W5 only if W4=1-3
A16: Week 2 | B16: W1, W2 | C16: W6 problems | D16: W7 bonus-unit effect | E16: W3 if W2=No
A17: Week 3 | B17: W1, W2 | C17: W8 who cooked | D17: W4 appliance use | E17: W3 if W2=No
A18: Week 4 | B18: Monthly module runs instead | C18: - | D18: - | E18: -
A21: Operating rules
A22: - Send at each household's preferred time (B24). Default 7pm if unanswered.
A23: - Response window 48h. One reminder (SYS_REMIND) at 24h. Credit only on full completion.
A24: - Unparseable reply: send SYS_INVALID once, accept next reply, log raw text.
A25: - 3 consecutive missed weekly surveys: pause weekly, keep monthly, send re-engagement message.
A26: - STOP or ACHA at any time: confirm with SYS_OPTOUT, cease all sends, keep consent log.
A27: - Never send more than one survey session per day, and none on Sundays.

Sheet Incentive design
A1: Reward sizing and credit-window experiment
A3: Assumptions (edit blue cells)
A4: Tariff (KSh per kWh) | B4: 25
A5: Energy for one EPC meal (kWh) | B5: 0.4
A6: Daytime window start | B6: 10:00
A7: Daytime window end | B7: 15:00
A9: Reward schedule
A10: Survey | B10: Reward (kWh) | C10: Cost (KSh) | D10: EPC meals equivalent
A11: Enrolment welcome | B11: 0.5 | C11: =B11*$B$4 -> 12.5 | D11: =ROUND(B11/$B$5,1) -> 1.3
A12: Baseline session (x3) | B12: 1 | C12: =B12*$B$4 -> 25 | D12: =ROUND(B12/$B$5,1) -> 2.5
A13: Weekly pulse | B13: 0.4 | C13: =B13*$B$4 -> 10 | D13: =ROUND(B13/$B$5,1) -> 1
A14: Monthly | B14: 0.7 | C14: =B14*$B$4 -> 17.5 | D14: =ROUND(B14/$B$5,1) -> 1.8
A15: Quarterly | B15: 1 | C15: =B15*$B$4 -> 25 | D15: =ROUND(B15/$B$5,1) -> 2.5
A16: 4-week streak bonus | B16: 0.5 | C16: =B16*$B$4 -> 12.5 | D16: =ROUND(B16/$B$5,1) -> 1.3
A17: Re-baseline (month 12) | B17: 2 | C17: =B17*$B$4 -> 50 | D17: =ROUND(B17/$B$5,1) -> 5
A19: Principle: the weekly reward should equal roughly one EPC meal, so trying electric cooking at midday costs nothing.
A22: Randomised credit-window arms
A23: Arm | B23: Credit validity | C23: Share of households | D23: What it tests
A24: A | B24: Daytime only (10am-3pm) | C24: 40% | D24: Does a time-limited credit shift cooking into the solar window?
A25: B | B25: Anytime (control) | C25: 40% | D25: Reward effect without any time constraint
A26: C | B26: Daytime only, double value | C26: 20% | D26: Dose response: is a bigger daytime credit more effective?
A28: Randomise at household level, stratified by village and EPC ownership (B7). Because every completed survey earns a credit, the credit window itself must be randomised - otherwise the survey reward and the daytime nudge are confounded. Outcome = daytime share of household kWh from the smart meters.

Sheet Codebook
A1: Variable | B1: QID | C1: Module | D1: Value | E1: Label (English) | F1: Label (Kiswahili)
A2: lang_pref | B2: S0 | C2: Enrolment & consent | D2: 1 | E2: Kiswahili | F2: Kiswahili
A3: lang_pref | B3: S0 | C3: Enrolment & consent | D3: 2 | E3: English | F3: English
A4: consent | B4: S1 | C4: Enrolment & consent | D4: 1 | E4: YES | F4: NDIYO
A5: consent | B5: S1 | C5: Enrolment & consent | D5: 2 | E5: NO | F5: HAPANA
A6: main_cook | B6: C1 | C6: Enrolment & consent | D6: 1 | E6: Yes | F6: Ndiyo
A7: main_cook | B7: C1 | C7: Enrolment & consent | D7: 2 | E7: I cook sometimes | F7: Napika mara kwa mara tu
A8: main_cook | B8: C1 | C8: Enrolment & consent | D8: 3 | E8: I rarely cook | F8: Sipiki sana
A9: hh_size | B9: B1 | C9: Baseline | D9: 1-30 | E9: Number (1-30) | F9: Number (1-30)
A10: hh_under5 | B10: B2 | C10: Baseline | D10: 0-15 | E10: Number (0-15) | F10: Number (0-15)
A11: phone_owner | B11: B3 | C11: Baseline | D11: 1 | E11: Mine | F11: Yangu
A12: phone_owner | B12: B3 | C12: Baseline | D12: 2 | E12: My spouse's | F12: Ya mke/mume wangu
A13: phone_owner | B13: B3 | C13: Baseline | D13: 3 | E13: Shared family phone | F13: Ya familia
A14: phone_owner | B14: B3 | C14: Baseline | D14: 4 | E14: Other | F14: Nyingine
A15: income_src | B15: B4 | C15: Baseline | D15: 1 | E15: Farming | F15: Kilimo
A16: income_src | B16: B4 | C16: Baseline | D16: 2 | E16: Own business | F16: Biashara
A17: income_src | B17: B4 | C17: Baseline | D17: 3 | E17: Casual work | F17: Vibarua
A18: income_src | B18: B4 | C18: Baseline | D18: 4 | E18: Salary | F18: Mshahara
A19: income_src | B19: B4 | C19: Baseline | D19: 5 | E19: Other | F19: Nyingine
A20: fuel_decider | B20: B5 | C20: Baseline | D20: 1 | E20: Me | F20: Mimi
A21: fuel_decider | B21: B5 | C21: Baseline | D21: 2 | E21: My spouse | F21: Mke/mume wangu
A22: fuel_decider | B22: B5 | C22: Baseline | D22: 3 | E22: We decide together | F22: Tunaamua pamoja
... A193: q_wtp_lunch | B193: Q5 | C193: Quarterly | D193: 5 | E193: Over KSh40 | F193: Zaidi ya KSh40
A194: q_open_feedback | B194: Q6 | C194: Quarterly | D194: Free text | E194: Free text | F194: Free text
